<?xml version="1.0" ?>
<sdf version="1.8">
    <model name="my_robot">
        <pose>0 0 0.05 0 0 0</pose>
        
        <!-- Base Footprint (for Nav2 compatibility) -->
        <link name="base_footprint"/>
        
        <link name="chassis">
            <pose>0 0 0.05 0 0 0</pose>
            <inertial>
                <pose>0 0 0.1 0 0 0</pose>
                <mass>15.0</mass>
                <inertia>
                    <ixx>0.8</ixx><ixy>0</ixy><ixz>0</ixz>
                    <iyy>1.0</iyy><iyz>0</iyz>
                    <izz>0.5</izz>
                </inertia>
            </inertial>
            
            <visual name="base_vis">
                <geometry><box><size>0.4 0.3 0.1</size></box></geometry>
                <material><ambient>0.2 0.2 0.2 1</ambient></material>
            </visual>
            <collision name="base_col">
                <geometry><box><size>0.4 0.3 0.1</size></box></geometry>
            </collision>
            
            <!-- Direk (Mast) -->
            <visual name="mast_vis">
                <pose>0 0 0.5 0 0 0</pose>
                <geometry><box><size>0.05 0.05 0.9</size></box></geometry>
                <material><ambient>0.8 0.8 0.8 1</ambient></material>
            </visual>
            <collision name="mast_col">
                <pose>0 0 0.5 0 0 0</pose>
                <geometry><box><size>0.05 0.05 0.9</size></box></geometry>
            </collision>

            <!-- Kamera (Tepede - Hafif Yukarı Bakış) -->
            <sensor name="camera" type="camera">
                <pose>0.05 0 0.95 0 -0.2 0</pose>
                <topic>camera</topic>
                <update_rate>30</update_rate>
                <camera>
                    <horizontal_fov>1.2</horizontal_fov>
                    <image><width>640</width><height>480</height></image>
                </camera>
                <visualize>true</visualize>
            </sensor>
            
            <!-- Lidar (Base seviyesinde - Nav2 uyumlu) -->
            <sensor name="lidar" type="gpu_lidar">
                <pose>0.0 0 0.17 0 0 0</pose>
                <topic>scan</topic>
                <update_rate>10</update_rate>
                <gz_frame_id>base_scan</gz_frame_id>
                <lidar>
                    <scan>
                        <horizontal>
                            <samples>360</samples>
                            <resolution>1</resolution>
                            <min_angle>-3.14159</min_angle>
                            <max_angle>3.14159</max_angle>
                        </horizontal>
                    </scan>
                    <range>
                        <min>0.05</min>
                        <max>10.0</max>
                    </range>
                </lidar>
            </sensor>
            
            <!-- IMU Sensor -->
            <sensor name="imu" type="imu">
                <always_on>true</always_on>
                <update_rate>200</update_rate>
                <topic>imu</topic>
            </sensor>
        </link>
        
        <!-- Base Scan Link (for TF compatibility) -->
        <link name="base_scan">
            <pose>0.0 0 0.17 0 0 0</pose>
        </link>
        
        <link name="left_wheel">
            <pose>0 0.17 0.05 -1.5708 0 0</pose>
            <inertial>
                <mass>0.5</mass>
                <inertia>
                    <ixx>0.001</ixx><ixy>0</ixy><ixz>0</ixz>
                    <iyy>0.001</iyy><iyz>0</iyz>
                    <izz>0.001</izz>
                </inertia>
            </inertial>
            <visual name="v">
                <geometry><cylinder><radius>0.05</radius><length>0.04</length></cylinder></geometry>
                <material><ambient>0.1 0.1 0.1 1</ambient></material>
            </visual>
            <collision name="c">
                <geometry><cylinder><radius>0.05</radius><length>0.04</length></cylinder></geometry>
                <surface>
                    <friction>
                        <ode><mu>100000.0</mu><mu2>100000.0</mu2></ode>
                    </friction>
                </surface>
            </collision>
        </link>
        
        <link name="right_wheel">
            <pose>0 -0.17 0.05 -1.5708 0 0</pose>
            <inertial>
                <mass>0.5</mass>
                <inertia>
                    <ixx>0.001</ixx><ixy>0</ixy><ixz>0</ixz>
                    <iyy>0.001</iyy><iyz>0</iyz>
                    <izz>0.001</izz>
                </inertia>
            </inertial>
            <visual name="v">
                <geometry><cylinder><radius>0.05</radius><length>0.04</length></cylinder></geometry>
                <material><ambient>0.1 0.1 0.1 1</ambient></material>
            </visual>
            <collision name="c">
                <geometry><cylinder><radius>0.05</radius><length>0.04</length></cylinder></geometry>
                <surface>
                    <friction>
                        <ode><mu>100000.0</mu><mu2>100000.0</mu2></ode>
                    </friction>
                </surface>
            </collision>
        </link>
        
        <link name="caster">
            <pose>-0.15 0 0.025 0 0 0</pose>
            <inertial>
                <mass>0.1</mass>
                <inertia>
                    <ixx>0.0001</ixx><ixy>0</ixy><ixz>0</ixz>
                    <iyy>0.0001</iyy><iyz>0</iyz>
                    <izz>0.0001</izz>
                </inertia>
            </inertial>
            <visual name="v">
                <geometry><sphere><radius>0.025</radius></sphere></geometry>
                <material><ambient>0.3 0.3 0.3 1</ambient></material>
            </visual>
            <collision name="c">
                <geometry><sphere><radius>0.025</radius></sphere></geometry>
                <surface>
                    <friction>
                        <ode><mu>0.0</mu><mu2>0.0</mu2></ode>
                    </friction>
                </surface>
            </collision>
        </link>
        
        <!-- Joints -->
        <joint name="base_joint" type="fixed">
            <parent>base_footprint</parent>
            <child>chassis</child>
        </joint>
        
        <joint name="scan_joint" type="fixed">
            <parent>chassis</parent>
            <child>base_scan</child>
        </joint>
        
        <joint name="left_wheel_joint" type="revolute">
            <parent>chassis</parent>
            <child>left_wheel</child>
            <axis><xyz>0 0 1</xyz></axis>
        </joint>
        
        <joint name="right_wheel_joint" type="revolute">
            <parent>chassis</parent>
            <child>right_wheel</child>
            <axis><xyz>0 0 1</xyz></axis>
        </joint>
        
        <joint name="caster_joint" type="ball">
            <parent>chassis</parent>
            <child>caster</child>
        </joint>
        
        <!-- Diff Drive Plugin -->
        <plugin filename="gz-sim-diff-drive-system" name="gz::sim::systems::DiffDrive">
            <left_joint>left_wheel_joint</left_joint>
            <right_joint>right_wheel_joint</right_joint>
            <wheel_separation>0.34</wheel_separation>
            <wheel_radius>0.05</wheel_radius>
            <max_linear_acceleration>1.0</max_linear_acceleration>
            <topic>cmd_vel</topic>
            <odom_topic>odom</odom_topic>
            <frame_id>odom</frame_id>
            <child_frame_id>base_footprint</child_frame_id>
            <odom_publisher_frequency>30</odom_publisher_frequency>
            <tf_topic>/tf</tf_topic>
        </plugin>
        
        <!-- Joint State Publisher Plugin -->
        <plugin filename="gz-sim-joint-state-publisher-system" name="gz::sim::systems::JointStatePublisher">
            <topic>joint_states</topic>
            <joint_name>left_wheel_joint</joint_name>
            <joint_name>right_wheel_joint</joint_name>
        </plugin>
        
    </model>
</sdf>
